<!DOCTYPE html>
<html lang="en">
<head>
    <meta charset="UTF-8">
    <title>Title</title>
</head>
<body>

</body>
<script>
    function* g() {
        yield 1;
        console.log('throwing an exception');
        throw new Error('generator broke!');
        yield 2;
        yield 3;
    }

    function log(generator) {
        let v;
        console.log('starting generator');
        try {
            v = generator.next();
            console.log('第一次运行next方法', v);
        } catch (err) {
            console.log('捕捉错误', v);
        }
        try {
            v = generator.next();
            console.log('第二次运行next方法', v);
        } catch (err) {
            console.log('捕捉错误', v);
        }
        try {
            v = generator.next();
            console.log('第三次运行next方法', v);
        } catch (err) {
            console.log('捕捉错误', v);
        }
        console.log('caller done');
    }

    log(g());
    //一旦Generator执行过程中抛出错误，且没有被内部捕获，就不会再执行下去了。如果此后还调用next方法，将返回一个value属性等于undefined、done属性等于true的对象，即JavaScript引擎认为这个Generator已经运行结束了。
</script>
</html>